Workbook

Sheet RawData
A1: Full Name | B1: Email | C1: Department | D1: Join Date | E1: End Date | F1: Salary | G1: Bonus %
A2: Employee 1 | B2: #ERROR | C2: Sales | D2: 44844 | E2: 44895 | F2: 86422 | G2: 0.06
A3: Employee 2 | B3: emp2@company.com | C3: Finance | D3: 45182 | E3: 45224 | F3: 45795 | G3: 0.12
A4: Employee 3 | B4: emp3@company.com | D4: 44784 | E4: 44806 | F4: 30860 | G4: 0.13
A5: Employee 4 | B5: emp4@company.com | C5: IT | D5: 44723 | E5: 44777 | F5: 68158 | G5: 0.1
A6: Employee 5 | B6: emp5@company.com | C6: HR | D6: 45077 | E6: 45101 | F6: 84343 | G6: 0.22
A7: Employee 6 | B7: emp6@company.com | D7: 44722 | E7: 44778 | F7: 74732 | G7: 0.12
A8: Employee 7 | B8: emp7@company.com | C8: Finance | D8: 44940 | E8: 44962 | F8: 41284 | G8: 0.11
A9: Employee 8 | B9: emp8@company.com | C9: HR | D9: 44710 | E9: 44753 | F9: 84886 | G9: 0.16
A10: Employee 9 | B10: emp9@company.com | C10: Finance | D10: 45205 | E10: 45217 | F10: 36265 | G10: 0.08
A11: Employee 10 | B11: emp10@company.com | C11: Marketing | D11: 45057 | E11: 45105 | F11: 46850 | G11: 0.21
A12: Employee 11 | B12: emp11@company.com | D12: 44918 | E12: 44938 | F12: 67194 | G12: 0.06
A13: Employee 12 | B13: emp12@company.com | C13: Sales | D13: 44923 | E13: 44946 | F13: 51962 | G13: 0.25
A14: Employee 13 | B14: emp13@company.com | C14: Sales | D14: 44726 | E14: 44767 | F14: 77191 | G14: 0.2
A15: Employee 14 | B15: emp14@company.com | C15: Marketing | D15: 44662 | E15: 44695 | F15: 74131 | G15: 0.09
A16: Employee 15 | B16: emp15@company.com | C16: Finance | D16: 44916 | E16: 44952 | F16: 46023 | G16: 0.05
A17: Employee 16 | B17: #ERROR | C17: HR | D17: 45138 | E17: 45181 | F17: 71090 | G17: 0.21
A18: Employee 17 | B18: emp17@company.com | D18: 45067 | E18: 45096 | F18: 31685 | G18: 0.19
A19: Employee 18 | B19: emp18@company.com | C19: Marketing | D19: 45216 | E19: 45252 | F19: 30769 | G19: 0.2
A20: Employee 19 | B20: emp19@company.com | D20: 44770 | E20: 44793 | F20: 89735 | G20: 0.2
A21: Employee 20 | B21: emp20@company.com | C21: Marketing | D21: 44661 | E21: 44717 | F21: 86101 | G21: 0.06
A22: Employee 21 | B22: emp21@company.com | C22: HR | D22: 45339 | E22: 45388 | F22: 32433 | G22: 0.12
A23: Employee 22 | B23: emp22@company.com | C23: Finance | D23: 44836 | E23: 44864 | F23: 35311 | G23: 0.07
A24: Employee 23 | B24: emp23@company.com | C24: Finance | D24: 45213 | E24: 45228 | F24: 67819 | G24: 0.22
A25: Employee 24 | B25: emp24@company.com | D25: 45164 | E25: 45182 | F25: 69188 | G25: 0.17
A26: Employee 25 | B26: emp25@company.com | C26: Finance | D26: 44687 | E26: 44733 | F26: 47568 | G26: 0.12
A27: Employee 26 | B27: emp26@company.com | C27: IT | D27: 44656 | E27: 44668 | F27: 83707 | G27: 0.06
A28: Employee 27 | B28: emp27@company.com | C28: Marketing | D28: 45239 | E28: 45299 | F28: 49769 | G28: 0.11
A29: Employee 28 | B29: emp28@company.com | C29: Finance | D29: 45100 | E29: 45157 | F29: 58693 | G29: 0.12
A30: Employee 29 | B30: emp29@company.com | D30: 45076 | E30: 45126 | F30: 36396 | G30: 0.2
A31: Employee 30 | B31: emp30@company.com | C31: Sales | D31: 44675 | E31: 44685 | F31: 57480 | G31: 0.18
A32: Employee 31 | B32: #ERROR | C32: HR | D32: 44808 | E32: 44828 | F32: 71434 | G32: 0.23
A33: Employee 32 | B33: emp32@company.com | C33: Marketing | D33: 45270 | E33: 45310 | F33: 55658 | G33: 0.14
A34: Employee 33 | B34: emp33@company.com | C34: HR | D34: 44804 | E34: 44826 | F34: 48942 | G34: 0.07
A35: Employee 34 | B35: emp34@company.com | C35: IT | D35: 45275 | E35: 45319 | F35: 87001 | G35: 0.19
A36: Employee 35 | B36: emp35@company.com | C36: HR | D36: 45356 | E36: 45406 | F36: 48431 | G36: 0.2
A37: Employee 36 | B37: emp36@company.com | C37: Marketing | D37: 44700 | E37: 44730 | F37: 32747 | G37: 0.16
A38: Employee 37 | B38: emp37@company.com | C38: IT | D38: 44760 | E38: 44816 | F38: 88319 | G38: 0.2
A39: Employee 38 | B39: emp38@company.com | D39: 44980 | E39: 45010 | F39: 89150 | G39: 0.15
A40: Employee 39 | B40: emp39@company.com | C40: Finance | D40: 44812 | E40: 44835 | F40: 30189 | G40: 0.15
...

Sheet DepartmentData
A1: Department | B1: Department Head | C1: Location
A2: HR | B2: Alice | C2: Mumbai
A3: Sales | B3: Bob | C3: Delhi
A4: Marketing | B4: Charlie | C4: Bangalore
A5: IT | B5: Diana | C5: Hyderabad
A6: Finance | B6: Ethan | C6: Pune

Sheet MoreEmployees
A1: Full Name | B1: Email | C1: Department | D1: Join Date | E1: End Date | F1: Salary | G1: Bonus %
A2: New Employee 101 | B2: newemp101@company.com | C2: Marketing | D2: 45329 | E2: 45483 | F2: 44688 | G2: 0.21
A3: New Employee 102 | B3: newemp102@company.com | C3: Finance | D3: 45453 | E3: 45475 | F3: 57342 | G3: 0.08
A4: New Employee 103 | B4: newemp103@company.com | C4: Finance | D4: 45299 | E4: 45486 | F4: 69157 | G4: 0.15
A5: New Employee 104 | B5: newemp104@company.com | C5: Sales | D5: 45303 | E5: 45498 | F5: 34327 | G5: 0.19
A6: New Employee 105 | B6: newemp105@company.com | C6: Marketing | D6: 45384 | E6: 45479 | F6: 72772 | G6: 0.22
A7: New Employee 106 | B7: newemp106@company.com | C7: Sales | D7: 45410 | E7: 45497 | F7: 72545 | G7: 0.12
A8: New Employee 107 | B8: newemp107@company.com | C8: Finance | D8: 45445 | E8: 45495 | F8: 32197 | G8: 0.09
A9: New Employee 108 | B9: newemp108@company.com | C9: HR | D9: 45299 | E9: 45476 | F9: 55509 | G9: 0.19
A10: New Employee 109 | B10: newemp109@company.com | C10: HR | D10: 45390 | E10: 45499 | F10: 66698 | G10: 0.21
A11: New Employee 110 | B11: newemp110@company.com | C11: IT | D11: 45359 | E11: 45490 | F11: 47087 | G11: 0.12

Sheet Combined
A1: Sr.No | B1: Full Name | C1: EmpID | D1: EmpDomain | E1: Department | F1: Join Date | G1: End Date | H1: Salary | I1: Bonus % | J1: Bonus Amount | K1: Department Head | L1: Location | M1: Email
A2: =ROW()-1 -> 1 | B2: =TRIM(RawData!A2) -> Employee 1 | C2: =IF(OR(EXACT(RawData!B2,"NA"),EXACT(RawData!B2,"#ERROR")),"emp"&A2,LEFT(RawData!B2,FIND("@",RawData!B2)-1)) -> emp1 | D2: =IF(OR(EXACT(RawData!B2,"NA"),EXACT(RawData!B2,"#ERROR")),"company.com",MID(RawData!B2,FIND("@",RawData!B2)+1,50)) -> company.com | E2: =IF(RawData!C2="","",RawData!C2) -> Sales | F2: =RawData!D2 -> 44844 | G2: =RawData!E2 -> 44895 | H2: =RawData!F2 -> 86422 | I2: =RawData!G2 -> 0.06 | J2: =H2*I2 -> 5185.32 | K2: =IFERROR(INDEX(DepartmentData!$B$2:$B$6,MATCH(E2,DepartmentData!$A$2:$A$6,0)),"") -> Bob | L2: =IFERROR(INDEX(DepartmentData!$C$2:$C$6,MATCH(E2,DepartmentData!$A$2:$A$6,0)),"") -> Delhi | M2: =IF(OR(EXACT(RawData!B2,"NA"),EXACT(RawData!B2,"#ERROR")),C2&"@"&D2,RawData!B2) -> emp1@company.com
A3: =ROW()-1 -> 2 | B3: =TRIM(RawData!A3) -> Employee 2 | C3: =IF(OR(EXACT(RawData!B3,"NA"),EXACT(RawData!B3,"#ERROR")),"emp"&A3,LEFT(RawData!B3,FIND("@",RawData!B3)-1)) -> emp2 | D3: =IF(OR(EXACT(RawData!B3,"NA"),EXACT(RawData!B3,"#ERROR")),"company.com",MID(RawData!B3,FIND("@",RawData!B3)+1,50)) -> company.com | E3: =IF(RawData!C3="","",RawData!C3) -> Finance | F3: =RawData!D3 -> 45182 | G3: =RawData!E3 -> 45224 | H3: =RawData!F3 -> 45795 | I3: =RawData!G3 -> 0.12 | J3: =H3*I3 -> 5495.4 | K3: =IFERROR(INDEX(DepartmentData!$B$2:$B$6,MATCH(E3,DepartmentData!$A$2:$A$6,0)),"") -> Ethan | L3: =IFERROR(INDEX(DepartmentData!$C$2:$C$6,MATCH(E3,DepartmentData!$A$2:$A$6,0)),"") -> Pune | M3: =IF(OR(EXACT(RawData!B3,"NA"),EXACT(RawData!B3,"#ERROR")),C3&"@"&D3,RawData!B3) -> emp2@company.com
A4: =ROW()-1 -> 3 | B4: =TRIM(RawData!A4) -> Employee 3 | C4: =IF(OR(EXACT(RawData!B4,"NA"),EXACT(RawData!B4,"#ERROR")),"emp"&A4,LEFT(RawData!B4,FIND("@",RawData!B4)-1)) -> emp3 | D4: =IF(OR(EXACT(RawData!B4,"NA"),EXACT(RawData!B4,"#ERROR")),"company.com",MID(RawData!B4,FIND("@",RawData!B4)+1,50)) -> company.com | E4: =IF(RawData!C4="","",RawData!C4) | F4: =RawData!D4 -> 44784 | G4: =RawData!E4 -> 44806 | H4: =RawData!F4 -> 30860 | I4: =RawData!G4 -> 0.13 | J4: =H4*I4 -> 4011.8 | K4: =IFERROR(INDEX(DepartmentData!$B$2:$B$6,MATCH(E4,DepartmentData!$A$2:$A$6,0)),"") | L4: =IFERROR(INDEX(DepartmentData!$C$2:$C$6,MATCH(E4,DepartmentData!$A$2:$A$6,0)),"") | M4: =IF(OR(EXACT(RawData!B4,"NA"),EXACT(RawData!B4,"#ERROR")),C4&"@"&D4,RawData!B4) -> emp3@company.com
A5: =ROW()-1 -> 4 | B5: =TRIM(RawData!A5) -> Employee 4 | C5: =IF(OR(EXACT(RawData!B5,"NA"),EXACT(RawData!B5,"#ERROR")),"emp"&A5,LEFT(RawData!B5,FIND("@",RawData!B5)-1)) -> emp4 | D5: =IF(OR(EXACT(RawData!B5,"NA"),EXACT(RawData!B5,"#ERROR")),"company.com",MID(RawData!B5,FIND("@",RawData!B5)+1,50)) -> company.com | E5: =IF(RawData!C5="","",RawData!C5) -> IT | F5: =RawData!D5 -> 44723 | G5: =RawData!E5 -> 44777 | H5: =RawData!F5 -> 68158 | I5: =RawData!G5 -> 0.1 | J5: =H5*I5 -> 6815.8 | K5: =IFERROR(INDEX(DepartmentData!$B$2:$B$6,MATCH(E5,DepartmentData!$A$2:$A$6,0)),"") -> Diana | L5: =IFERROR(INDEX(DepartmentData!$C$2:$C$6,MATCH(E5,DepartmentData!$A$2:$A$6,0)),"") -> Hyderabad | M5: =IF(OR(EXACT(RawData!B5,"NA"),EXACT(RawData!B5,"#ERROR")),C5&"@"&D5,RawData!B5) -> emp4@company.com
A6: =ROW()-1 -> 5 | B6: =TRIM(RawData!A6) -> Employee 5 | C6: =IF(OR(EXACT(RawData!B6,"NA"),EXACT(RawData!B6,"#ERROR")),"emp"&A6,LEFT(RawData!B6,FIND("@",RawData!B6)-1)) -> emp5 | D6: =IF(OR(EXACT(RawData!B6,"NA"),EXACT(RawData!B6,"#ERROR")),"company.com",MID(RawData!B6,FIND("@",RawData!B6)+1,50)) -> company.com | E6: =IF(RawData!C6="","",RawData!C6) -> HR | F6: =RawData!D6 -> 45077 | G6: =RawData!E6 -> 45101 | H6: =RawData!F6 -> 84343 | I6: =RawData!G6 -> 0.22 | J6: =H6*I6 -> 18555.46 | K6: =IFERROR(INDEX(DepartmentData!$B$2:$B$6,MATCH(E6,DepartmentData!$A$2:$A$6,0)),"") -> Alice | L6: =IFERROR(INDEX(DepartmentData!$C$2:$C$6,MATCH(E6,DepartmentData!$A$2:$A$6,0)),"") -> Mumbai | M6: =IF(OR(EXACT(RawData!B6,"NA"),EXACT(RawData!B6,"#ERROR")),C6&"@"&D6,RawData!B6) -> emp5@company.com
A7: =ROW()-1 -> 6 | B7: =TRIM(RawData!A7) -> Employee 6 | C7: =IF(OR(EXACT(RawData!B7,"NA"),EXACT(RawData!B7,"#ERROR")),"emp"&A7,LEFT(RawData!B7,FIND("@",RawData!B7)-1)) -> emp6 | D7: =IF(OR(EXACT(RawData!B7,"NA"),EXACT(RawData!B7,"#ERROR")),"company.com",MID(RawData!B7,FIND("@",RawData!B7)+1,50)) -> company.com | E7: =IF(RawData!C7="","",RawData!C7) | F7: =RawData!D7 -> 44722 | G7: =RawData!E7 -> 44778 | H7: =RawData!F7 -> 74732 | I7: =RawData!G7 -> 0.12 | J7: =H7*I7 -> 8967.84 | K7: =IFERROR(INDEX(DepartmentData!$B$2:$B$6,MATCH(E7,DepartmentData!$A$2:$A$6,0)),"") | L7: =IFERROR(INDEX(DepartmentData!$C$2:$C$6,MATCH(E7,DepartmentData!$A$2:$A$6,0)),"") | M7: =IF(OR(EXACT(RawData!B7,"NA"),EXACT(RawData!B7,"#ERROR")),C7&"@"&D7,RawData!B7) -> emp6@company.com
A8: =ROW()-1 -> 7 | B8: =TRIM(RawData!A8) -> Employee 7 | C8: =IF(OR(EXACT(RawData!B8,"NA"),EXACT(RawData!B8,"#ERROR")),"emp"&A8,LEFT(RawData!B8,FIND("@",RawData!B8)-1)) -> emp7 | D8: =IF(OR(EXACT(RawData!B8,"NA"),EXACT(RawData!B8,"#ERROR")),"company.com",MID(RawData!B8,FIND("@",RawData!B8)+1,50)) -> company.com | E8: =IF(RawData!C8="","",RawData!C8) -> Finance | F8: =RawData!D8 -> 44940 | G8: =RawData!E8 -> 44962 | H8: =RawData!F8 -> 41284 | I8: =RawData!G8 -> 0.11 | J8: =H8*I8 -> 4541.24 | K8: =IFERROR(INDEX(DepartmentData!$B$2:$B$6,MATCH(E8,DepartmentData!$A$2:$A$6,0)),"") -> Ethan | L8: =IFERROR(INDEX(DepartmentData!$C$2:$C$6,MATCH(E8,DepartmentData!$A$2:$A$6,0)),"") -> Pune | M8: =IF(OR(EXACT(RawData!B8,"NA"),EXACT(RawData!B8,"#ERROR")),C8&"@"&D8,RawData!B8) -> emp7@company.com
A9: =ROW()-1 -> 8 | B9: =TRIM(RawData!A9) -> Employee 8 | C9: =IF(OR(EXACT(RawData!B9,"NA"),EXACT(RawData!B9,"#ERROR")),"emp"&A9,LEFT(RawData!B9,FIND("@",RawData!B9)-1)) -> emp8 | D9: =IF(OR(EXACT(RawData!B9,"NA"),EXACT(RawData!B9,"#ERROR")),"company.com",MID(RawData!B9,FIND("@",RawData!B9)+1,50)) -> company.com | E9: =IF(RawData!C9="","",RawData!C9) -> HR | F9: =RawData!D9 -> 44710 | G9: =RawData!E9 -> 44753 | H9: =RawData!F9 -> 84886 | I9: =RawData!G9 -> 0.16 | J9: =H9*I9 -> 13581.76 | K9: =IFERROR(INDEX(DepartmentData!$B$2:$B$6,MATCH(E9,DepartmentData!$A$2:$A$6,0)),"") -> Alice | L9: =IFERROR(INDEX(DepartmentData!$C$2:$C$6,MATCH(E9,DepartmentData!$A$2:$A$6,0)),"") -> Mumbai | M9: =IF(OR(EXACT(RawData!B9,"NA"),EXACT(RawData!B9,"#ERROR")),C9&"@"&D9,RawData!B9) -> emp8@company.com
A10: =ROW()-1 -> 9 | B10: =TRIM(RawData!A10) -> Employee 9 | C10: =IF(OR(EXACT(RawData!B10,"NA"),EXACT(RawData!B10,"#ERROR")),"emp"&A10,LEFT(RawData!B10,FIND("@",RawData!B10)-1)) -> emp9 | D10: =IF(OR(EXACT(RawData!B10,"NA"),EXACT(RawData!B10,"#ERROR")),"company.com",MID(RawData!B10,FIND("@",RawData!B10)+1,50)) -> company.com | E10: =IF(RawData!C10="","",RawData!C10) -> Finance | F10: =RawData!D10 -> 45205 | G10: =RawData!E10 -> 45217 | H10: =RawData!F10 -> 36265 | I10: =RawData!G10 -> 0.08 | J10: =H10*I10 -> 2901.2 | K10: =IFERROR(INDEX(DepartmentData!$B$2:$B$6,MATCH(E10,DepartmentData!$A$2:$A$6,0)),"") -> Ethan | L10: =IFERROR(INDEX(DepartmentData!$C$2:$C$6,MATCH(E10,DepartmentData!$A$2:$A$6,0)),"") -> Pune | M10: =IF(OR(EXACT(RawData!B10,"NA"),EXACT(RawData!B10,"#ERROR")),C10&"@"&D10,RawData!B10) -> emp9@company.com
A11: =ROW()-1 -> 10 | B11: =TRIM(RawData!A11) -> Employee 10 | C11: =IF(OR(EXACT(RawData!B11,"NA"),EXACT(RawData!B11,"#ERROR")),"emp"&A11,LEFT(RawData!B11,FIND("@",RawData!B11)-1)) -> emp10 | D11: =IF(OR(EXACT(RawData!B11,"NA"),EXACT(RawData!B11,"#ERROR")),"company.com",MID(RawData!B11,FIND("@",RawData!B11)+1,50)) -> company.com | E11: =IF(RawData!C11="","",RawData!C11) -> Marketing | F11: =RawData!D11 -> 45057 | G11: =RawData!E11 -> 45105 | H11: =RawData!F11 -> 46850 | I11: =RawData!G11 -> 0.21 | J11: =H11*I11 -> 9838.5 | K11: =IFERROR(INDEX(DepartmentData!$B$2:$B$6,MATCH(E11,DepartmentData!$A$2:$A$6,0)),"") -> Charlie | L11: =IFERROR(INDEX(DepartmentData!$C$2:$C$6,MATCH(E11,DepartmentData!$A$2:$A$6,0)),"") -> Bangalore | M11: =IF(OR(EXACT(RawData!B11,"NA"),EXACT(RawData!B11,"#ERROR")),C11&"@"&D11,RawData!B11) -> emp10@company.com
A12: =ROW()-1 -> 11 | B12: =TRIM(RawData!A12) -> Employee 11 | C12: =IF(OR(EXACT(RawData!B12,"NA"),EXACT(RawData!B12,"#ERROR")),"emp"&A12,LEFT(RawData!B12,FIND("@",RawData!B12)-1)) -> emp11 | D12: =IF(OR(EXACT(RawData!B12,"NA"),EXACT(RawData!B12,"#ERROR")),"company.com",MID(RawData!B12,FIND("@",RawData!B12)+1,50)) -> company.com | E12: =IF(RawData!C12="","",RawData!C12) | F12: =RawData!D12 -> 44918 | G12: =RawData!E12 -> 44938 | H12: =RawData!F12 -> 67194 | I12: =RawData!G12 -> 0.06 | J12: =H12*I12 -> 4031.64 | K12: =IFERROR(INDEX(DepartmentData!$B$2:$B$6,MATCH(E12,DepartmentData!$A$2:$A$6,0)),"") | L12: =IFERROR(INDEX(DepartmentData!$C$2:$C$6,MATCH(E12,DepartmentData!$A$2:$A$6,0)),"") | M12: =IF(OR(EXACT(RawData!B12,"NA"),EXACT(RawData!B12,"#ERROR")),C12&"@"&D12,RawData!B12) -> emp11@company.com
A13: =ROW()-1 -> 12 | B13: =TRIM(RawData!A13) -> Employee 12 | C13: =IF(OR(EXACT(RawData!B13,"NA"),EXACT(RawData!B13,"#ERROR")),"emp"&A13,LEFT(RawData!B13,FIND("@",RawData!B13)-1)) -> emp12 | D13: =IF(OR(EXACT(RawData!B13,"NA"),EXACT(RawData!B13,"#ERROR")),"company.com",MID(RawData!B13,FIND("@",RawData!B13)+1,50)) -> company.com | E13: =IF(RawData!C13="","",RawData!C13) -> Sales | F13: =RawData!D13 -> 44923 | G13: =RawData!E13 -> 44946 | H13: =RawData!F13 -> 51962 | I13: =RawData!G13 -> 0.25 | J13: =H13*I13 -> 12990.5 | K13: =IFERROR(INDEX(DepartmentData!$B$2:$B$6,MATCH(E13,DepartmentData!$A$2:$A$6,0)),"") -> Bob | L13: =IFERROR(INDEX(DepartmentData!$C$2:$C$6,MATCH(E13,DepartmentData!$A$2:$A$6,0)),"") -> Delhi | M13: =IF(OR(EXACT(RawData!B13,"NA"),EXACT(RawData!B13,"#ERROR")),C13&"@"&D13,RawData!B13) -> emp12@company.com
... A101: =ROW()-1 -> 100 | B101: =TRIM(RawData!A101) -> Employee 100 | C101: =IF(OR(EXACT(RawData!B101,"NA"),EXACT(RawData!B101,"#ERROR")),"emp"&A101,LEFT(RawData!B101,FIND("@",RawData!B101)-1)) -> emp100 | D101: =IF(OR(EXACT(RawData!B101,"NA"),EXACT(RawData!B101,"#ERROR")),"company.com",MID(RawData!B101,FIND("@",RawData!B101)+1,50)) -> company.com | E101: =IF(RawData!C101="","",RawData!C101) -> Finance | F101: =RawData!D101 -> 45119 | G101: =RawData!E101 -> 45140 | H101: =RawData!F101 -> 55851 | I101: =RawData!G101 -> 0.2 | J101: =H101*I101 -> 11170.2 | K101: =IFERROR(INDEX(DepartmentData!$B$2:$B$6,MATCH(E101,DepartmentData!$A$2:$A$6,0)),"") -> Ethan | L101: =IFERROR(INDEX(DepartmentData!$C$2:$C$6,MATCH(E101,DepartmentData!$A$2:$A$6,0)),"") -> Pune | M101: =IF(OR(EXACT(RawData!B101,"NA"),EXACT(RawData!B101,"#ERROR")),C101&"@"&D101,RawData!B101) -> emp100@company.com
A102: =ROW()-1 -> 101 | B102: =TRIM(MoreEmployees!A2) -> New Employee 101 | C102: =IF(OR(EXACT(MoreEmployees!B2,"NA"),EXACT(MoreEmployees!B2,"#ERROR")),"emp"&A102,LEFT(MoreEmployees!B2,FIND("@",MoreEmployees!B2)-1)) -> newemp101 | D102: =IF(OR(EXACT(MoreEmployees!B2,"NA"),EXACT(MoreEmployees!B2,"#ERROR")),"company.com",MID(MoreEmployees!B2,FIND("@",MoreEmployees!B2)+1,50)) -> company.com | E102: =IF(MoreEmployees!C2="","",MoreEmployees!C2) -> Marketing | F102: =MoreEmployees!D2 -> 45329 | G102: =MoreEmployees!E2 -> 45483 | H102: =MoreEmployees!F2 -> 44688 | I102: =MoreEmployees!G2 -> 0.21 | J102: =H102*I102 -> 9384.48 | K102: =IFERROR(INDEX(DepartmentData!$B$2:$B$6,MATCH(E102,DepartmentData!$A$2:$A$6,0)),"") -> Charlie | L102: =IFERROR(INDEX(DepartmentData!$C$2:$C$6,MATCH(E102,DepartmentData!$A$2:$A$6,0)),"") -> Bangalore | M102: =IF(OR(EXACT(MoreEmployees!B2,"NA"),EXACT(MoreEmployees!B2,"#ERROR")),C102&"@"&D102,MoreEmployees!B2) -> newemp101@company.com
A103: =ROW()-1 -> 102 | B103: =TRIM(MoreEmployees!A3) -> New Employee 102 | C103: =IF(OR(EXACT(MoreEmployees!B3,"NA"),EXACT(MoreEmployees!B3,"#ERROR")),"emp"&A103,LEFT(MoreEmployees!B3,FIND("@",MoreEmployees!B3)-1)) -> newemp102 | D103: =IF(OR(EXACT(MoreEmployees!B3,"NA"),EXACT(MoreEmployees!B3,"#ERROR")),"company.com",MID(MoreEmployees!B3,FIND("@",MoreEmployees!B3)+1,50)) -> company.com | E103: =IF(MoreEmployees!C3="","",MoreEmployees!C3) -> Finance | F103: =MoreEmployees!D3 -> 45453 | G103: =MoreEmployees!E3 -> 45475 | H103: =MoreEmployees!F3 -> 57342 | I103: =MoreEmployees!G3 -> 0.08 | J103: =H103*I103 -> 4587.36 | K103: =IFERROR(INDEX(DepartmentData!$B$2:$B$6,MATCH(E103,DepartmentData!$A$2:$A$6,0)),"") -> Ethan | L103: =IFERROR(INDEX(DepartmentData!$C$2:$C$6,MATCH(E103,DepartmentData!$A$2:$A$6,0)),"") -> Pune | M103: =IF(OR(EXACT(MoreEmployees!B3,"NA"),EXACT(MoreEmployees!B3,"#ERROR")),C103&"@"&D103,MoreEmployees!B3) -> newemp102@company.com
A104: =ROW()-1 -> 103 | B104: =TRIM(MoreEmployees!A4) -> New Employee 103 | C104: =IF(OR(EXACT(MoreEmployees!B4,"NA"),EXACT(MoreEmployees!B4,"#ERROR")),"emp"&A104,LEFT(MoreEmployees!B4,FIND("@",MoreEmployees!B4)-1)) -> newemp103 | D104: =IF(OR(EXACT(MoreEmployees!B4,"NA"),EXACT(MoreEmployees!B4,"#ERROR")),"company.com",MID(MoreEmployees!B4,FIND("@",MoreEmployees!B4)+1,50)) -> company.com | E104: =IF(MoreEmployees!C4="","",MoreEmployees!C4) -> Finance | F104: =MoreEmployees!D4 -> 45299 | G104: =MoreEmployees!E4 -> 45486 | H104: =MoreEmployees!F4 -> 69157 | I104: =MoreEmployees!G4 -> 0.15 | J104: =H104*I104 -> 10373.55 | K104: =IFERROR(INDEX(DepartmentData!$B$2:$B$6,MATCH(E104,DepartmentData!$A$2:$A$6,0)),"") -> Ethan | L104: =IFERROR(INDEX(DepartmentData!$C$2:$C$6,MATCH(E104,DepartmentData!$A$2:$A$6,0)),"") -> Pune | M104: =IF(OR(EXACT(MoreEmployees!B4,"NA"),EXACT(MoreEmployees!B4,"#ERROR")),C104&"@"&D104,MoreEmployees!B4) -> newemp103@company.com
A105: =ROW()-1 -> 104 | B105: =TRIM(MoreEmployees!A5) -> New Employee 104 | C105: =IF(OR(EXACT(MoreEmployees!B5,"NA"),EXACT(MoreEmployees!B5,"#ERROR")),"emp"&A105,LEFT(MoreEmployees!B5,FIND("@",MoreEmployees!B5)-1)) -> newemp104 | D105: =IF(OR(EXACT(MoreEmployees!B5,"NA"),EXACT(MoreEmployees!B5,"#ERROR")),"company.com",MID(MoreEmployees!B5,FIND("@",MoreEmployees!B5)+1,50)) -> company.com | E105: =IF(MoreEmployees!C5="","",MoreEmployees!C5) -> Sales | F105: =MoreEmployees!D5 -> 45303 | G105: =MoreEmployees!E5 -> 45498 | H105: =MoreEmployees!F5 -> 34327 | I105: =MoreEmployees!G5 -> 0.19 | J105: =H105*I105 -> 6522.13 | K105: =IFERROR(INDEX(DepartmentData!$B$2:$B$6,MATCH(E105,DepartmentData!$A$2:$A$6,0)),"") -> Bob | L105: =IFERROR(INDEX(DepartmentData!$C$2:$C$6,MATCH(E105,DepartmentData!$A$2:$A$6,0)),"") -> Delhi | M105: =IF(OR(EXACT(MoreEmployees!B5,"NA"),EXACT(MoreEmployees!B5,"#ERROR")),C105&"@"&D105,MoreEmployees!B5) -> newemp104@company.com
A106: =ROW()-1 -> 105 | B106: =TRIM(MoreEmployees!A6) -> New Employee 105 | C106: =IF(OR(EXACT(MoreEmployees!B6,"NA"),EXACT(MoreEmployees!B6,"#ERROR")),"emp"&A106,LEFT(MoreEmployees!B6,FIND("@",MoreEmployees!B6)-1)) -> newemp105 | D106: =IF(OR(EXACT(MoreEmployees!B6,"NA"),EXACT(MoreEmployees!B6,"#ERROR")),"company.com",MID(MoreEmployees!B6,FIND("@",MoreEmployees!B6)+1,50)) -> company.com | E106: =IF(MoreEmployees!C6="","",MoreEmployees!C6) -> Marketing | F106: =MoreEmployees!D6 -> 45384 | G106: =MoreEmployees!E6 -> 45479 | H106: =MoreEmployees!F6 -> 72772 | I106: =MoreEmployees!G6 -> 0.22 | J106: =H106*I106 -> 16009.84 | K106: =IFERROR(INDEX(DepartmentData!$B$2:$B$6,MATCH(E106,DepartmentData!$A$2:$A$6,0)),"") -> Charlie | L106: =IFERROR(INDEX(DepartmentData!$C$2:$C$6,MATCH(E106,DepartmentData!$A$2:$A$6,0)),"") -> Bangalore | M106: =IF(OR(EXACT(MoreEmployees!B6,"NA"),EXACT(MoreEmployees!B6,"#ERROR")),C106&"@"&D106,MoreEmployees!B6) -> newemp105@company.com
A107: =ROW()-1 -> 106 | B107: =TRIM(MoreEmployees!A7) -> New Employee 106 | C107: =IF(OR(EXACT(MoreEmployees!B7,"NA"),EXACT(MoreEmployees!B7,"#ERROR")),"emp"&A107,LEFT(MoreEmployees!B7,FIND("@",MoreEmployees!B7)-1)) -> newemp106 | D107: =IF(OR(EXACT(MoreEmployees!B7,"NA"),EXACT(MoreEmployees!B7,"#ERROR")),"company.com",MID(MoreEmployees!B7,FIND("@",MoreEmployees!B7)+1,50)) -> company.com | E107: =IF(MoreEmployees!C7="","",MoreEmployees!C7) -> Sales | F107: =MoreEmployees!D7 -> 45410 | G107: =MoreEmployees!E7 -> 45497 | H107: =MoreEmployees!F7 -> 72545 | I107: =MoreEmployees!G7 -> 0.12 | J107: =H107*I107 -> 8705.4 | K107: =IFERROR(INDEX(DepartmentData!$B$2:$B$6,MATCH(E107,DepartmentData!$A$2:$A$6,0)),"") -> Bob | L107: =IFERROR(INDEX(DepartmentData!$C$2:$C$6,MATCH(E107,DepartmentData!$A$2:$A$6,0)),"") -> Delhi | M107: =IF(OR(EXACT(MoreEmployees!B7,"NA"),EXACT(MoreEmployees!B7,"#ERROR")),C107&"@"&D107,MoreEmployees!B7) -> newemp106@company.com
A108: =ROW()-1 -> 107 | B108: =TRIM(MoreEmployees!A8) -> New Employee 107 | C108: =IF(OR(EXACT(MoreEmployees!B8,"NA"),EXACT(MoreEmployees!B8,"#ERROR")),"emp"&A108,LEFT(MoreEmployees!B8,FIND("@",MoreEmployees!B8)-1)) -> newemp107 | D108: =IF(OR(EXACT(MoreEmployees!B8,"NA"),EXACT(MoreEmployees!B8,"#ERROR")),"company.com",MID(MoreEmployees!B8,FIND("@",MoreEmployees!B8)+1,50)) -> company.com | E108: =IF(MoreEmployees!C8="","",MoreEmployees!C8) -> Finance | F108: =MoreEmployees!D8 -> 45445 | G108: =MoreEmployees!E8 -> 45495 | H108: =MoreEmployees!F8 -> 32197 | I108: =MoreEmployees!G8 -> 0.09 | J108: =H108*I108 -> 2897.73 | K108: =IFERROR(INDEX(DepartmentData!$B$2:$B$6,MATCH(E108,DepartmentData!$A$2:$A$6,0)),"") -> Ethan | L108: =IFERROR(INDEX(DepartmentData!$C$2:$C$6,MATCH(E108,DepartmentData!$A$2:$A$6,0)),"") -> Pune | M108: =IF(OR(EXACT(MoreEmployees!B8,"NA"),EXACT(MoreEmployees!B8,"#ERROR")),C108&"@"&D108,MoreEmployees!B8) -> newemp107@company.com
A109: =ROW()-1 -> 108 | B109: =TRIM(MoreEmployees!A9) -> New Employee 108 | C109: =IF(OR(EXACT(MoreEmployees!B9,"NA"),EXACT(MoreEmployees!B9,"#ERROR")),"emp"&A109,LEFT(MoreEmployees!B9,FIND("@",MoreEmployees!B9)-1)) -> newemp108 | D109: =IF(OR(EXACT(MoreEmployees!B9,"NA"),EXACT(MoreEmployees!B9,"#ERROR")),"company.com",MID(MoreEmployees!B9,FIND("@",MoreEmployees!B9)+1,50)) -> company.com | E109: =IF(MoreEmployees!C9="","",MoreEmployees!C9) -> HR | F109: =MoreEmployees!D9 -> 45299 | G109: =MoreEmployees!E9 -> 45476 | H109: =MoreEmployees!F9 -> 55509 | I109: =MoreEmployees!G9 -> 0.19 | J109: =H109*I109 -> 10546.71 | K109: =IFERROR(INDEX(DepartmentData!$B$2:$B$6,MATCH(E109,DepartmentData!$A$2:$A$6,0)),"") -> Alice | L109: =IFERROR(INDEX(DepartmentData!$C$2:$C$6,MATCH(E109,DepartmentData!$A$2:$A$6,0)),"") -> Mumbai | M109: =IF(OR(EXACT(MoreEmployees!B9,"NA"),EXACT(MoreEmployees!B9,"#ERROR")),C109&"@"&D109,MoreEmployees!B9) -> newemp108@company.com
A110: =ROW()-1 -> 109 | B110: =TRIM(MoreEmployees!A10) -> New Employee 109 | C110: =IF(OR(EXACT(MoreEmployees!B10,"NA"),EXACT(MoreEmployees!B10,"#ERROR")),"emp"&A110,LEFT(MoreEmployees!B10,FIND("@",MoreEmployees!B10)-1)) -> newemp109 | D110: =IF(OR(EXACT(MoreEmployees!B10,"NA"),EXACT(MoreEmployees!B10,"#ERROR")),"company.com",MID(MoreEmployees!B10,FIND("@",MoreEmployees!B10)+1,50)) -> company.com | E110: =IF(MoreEmployees!C10="","",MoreEmployees!C10) -> HR | F110: =MoreEmployees!D10 -> 45390 | G110: =MoreEmployees!E10 -> 45499 | H110: =MoreEmployees!F10 -> 66698 | I110: =MoreEmployees!G10 -> 0.21 | J110: =H110*I110 -> 14006.58 | K110: =IFERROR(INDEX(DepartmentData!$B$2:$B$6,MATCH(E110,DepartmentData!$A$2:$A$6,0)),"") -> Alice | L110: =IFERROR(INDEX(DepartmentData!$C$2:$C$6,MATCH(E110,DepartmentData!$A$2:$A$6,0)),"") -> Mumbai | M110: =IF(OR(EXACT(MoreEmployees!B10,"NA"),EXACT(MoreEmployees!B10,"#ERROR")),C110&"@"&D110,MoreEmployees!B10) -> newemp109@company.com
A111: =ROW()-1 -> 110 | B111: =TRIM(MoreEmployees!A11) -> New Employee 110 | C111: =IF(OR(EXACT(MoreEmployees!B11,"NA"),EXACT(MoreEmployees!B11,"#ERROR")),"emp"&A111,LEFT(MoreEmployees!B11,FIND("@",MoreEmployees!B11)-1)) -> newemp110 | D111: =IF(OR(EXACT(MoreEmployees!B11,"NA"),EXACT(MoreEmployees!B11,"#ERROR")),"company.com",MID(MoreEmployees!B11,FIND("@",MoreEmployees!B11)+1,50)) -> company.com | E111: =IF(MoreEmployees!C11="","",MoreEmployees!C11) -> IT | F111: =MoreEmployees!D11 -> 45359 | G111: =MoreEmployees!E11 -> 45490 | H111: =MoreEmployees!F11 -> 47087 | I111: =MoreEmployees!G11 -> 0.12 | J111: =H111*I111 -> 5650.44 | K111: =IFERROR(INDEX(DepartmentData!$B$2:$B$6,MATCH(E111,DepartmentData!$A$2:$A$6,0)),"") -> Diana | L111: =IFERROR(INDEX(DepartmentData!$C$2:$C$6,MATCH(E111,DepartmentData!$A$2:$A$6,0)),"") -> Hyderabad | M111: =IF(OR(EXACT(MoreEmployees!B11,"NA"),EXACT(MoreEmployees!B11,"#ERROR")),C111&"@"&D111,MoreEmployees!B11) -> newemp110@company.com

Sheet PowerQuery_Steps
A1: How to Build This With Power Query in Excel
A3: 1. Load the source tables
A4: Data tab -> Get Data -> From Other Sources -> From Table/Range. Do this once for RawData, once for MoreEmployees, and once for DepartmentData. Each becomes its own query in the Power Query Editor.
A6: 2. Append RawData and MoreEmployees
A7: In the Power Query Editor, select the RawData query -> Home tab -> Append Queries -> Append Queries as New -> choose MoreEmployees as the table to append. This stacks all 110 employee rows into one query.
A9: 3. Trim the Full Name column
A10: Select the Full Name column -> Transform tab -> Format -> Trim. This removes the leading/trailing spaces present on some rows (e.g. ' Employee 1 ').
A12: 4. Split the Email column
A13: Select the Email column -> Home tab -> Split Column -> By Delimiter -> choose '@' as the delimiter, split at the first occurrence. This creates two new columns: EmpID and EmpDomain.
A15: 5. Handle the bad email rows
A16: For rows where Email was 'NA' or '#ERROR', the split will produce junk values. Use Transform -> Replace Values (or a Conditional Column) to detect these and replace EmpID with "emp" & [Sr.No] and EmpDomain with "company.com", matching the pattern every valid email follows.
A18: 6. Merge with DepartmentData
... A28: Home tab -> Close & Load To... -> choose a new worksheet (or 'Only Create Connection' if you just want it staged). This produces the same result as the 'Combined' sheet already built into this workbook with formulas.
